<?xml version="1.0" ?>
<!-- =================================================================================== -->
<!-- |    This document was autogenerated by xacro from src/puzzlebot_description/urdf/puzzlebot.urdf.xacro | -->
<!-- |    EDITING THIS FILE BY HAND IS NOT RECOMMENDED                                 | -->
<!-- =================================================================================== -->
<robot name="puzzlebot">
  <!--
      Materials for RVIZ visualization (rgb color only)
  -->
  <material name="black">
    <color rgba="0.0 0.0 0.0 1.0"/>
  </material>
  <material name="dark_grey">
    <color rgba="0.2 0.2 0.2 1.0"/>
  </material>
  <material name="light_grey">
    <color rgba="0.7 0.7 0.7 1.0"/>
  </material>
  <material name="yellow">
    <color rgba="0.95 0.76 0.05 1.0"/>
  </material>
  <material name="white">
    <color rgba="1.0 1.0 1.0 1.0"/>
  </material>
  <material name="red">
    <color rgba="0.80 0.13 0.13 1.0"/>
  </material>
  <material name="blue">
    <color rgba="0.20 0.24 0.29 1.0"/>
  </material>
  <material name="orange">
    <color rgba="1.0 0.1 0.0 1.0"/>
  </material>
  
 
  <!--
    base_footprint:reference frame fo assuming the robot is at z=0 (floor) -->
  <link name="base_footprint"/>
  <joint name="base_footprint_to_base_link" type="fixed">
    <parent link="base_footprint"/>
    <child link="base_link"/>
    <!-- the chassis lays on the floor considering wheels radius-->
    <origin rpy="0 0 0" xyz="0 0 0.05"/>
  </joint>

  <link name="base_link"/>
  <joint name="base_link_to_chassis" type="fixed">
    <parent link="base_link"/>
    <child link="chassis_link"/>
    <origin rpy="0 0 0" xyz="0 0 0"/>
  </joint>

  <link name="chassis_link">
    <visual>
      <origin rpy="1.570796326794895 0 3.14159265358979" xyz="0.050 0 0.0"/>
      <geometry>
        <mesh filename="../meshes/puzzlebot_chasis.obj"/>
      </geometry>
      <material name="white"/>
    </visual>
    <collision>
      <origin rpy="0 0 0" xyz="0 0 0"/>
      <geometry>
        <box size="0.2 0.16 0.06"/>
      </geometry>
    </collision>
    <inertial>
      <origin rpy="0 0 0" xyz="0 0 0"/>
      <mass value="0.71"/>
      <inertia ixx="0.0017276666666666666" ixy="0.0" ixz="0.0" iyy="0.002579666666666667" iyz="0.0" izz="0.0038813333333333334"/>
    </inertial>
  </link>

  <link name="caster_wheel_link">
    <visual>
      <origin rpy="1.57 0 0" xyz="0 0 0"/>
      <geometry>
        <mesh filename="../meshes/puzzlebot_caster_wheel.obj"/>
      </geometry>
      <material name="dark_grey"/>
    </visual>
    <collision>
      <origin rpy="0 0 0" xyz="0 0 0"/>
      <geometry>
        <sphere radius="0.0065"/>
      </geometry>
    </collision>
    <inertial>
      <origin rpy="0 0 0" xyz="0 0 0"/>
      <mass value="0.012"/>
      <inertia ixx="2.028e-07" ixy="0.0" ixz="0.0" iyy="2.028e-07" iyz="0.0" izz="2.028e-07"/>
    </inertial>
  </link>
  <joint name="chassis_to_caster" type="fixed">
    <parent link="chassis_link"/>
    <child link="caster_wheel_link"/>
    <origin rpy="0 0 0" xyz="-0.095 0.0 -0.0425"/>
  </joint>


  <!-- RIGHT WHEEL -->
  <link name="right_wheel_link">
    <visual>
      <origin rpy="0 0 0" xyz="0 0 0"/>
      <geometry>
        <mesh filename="../meshes/puzzlebot_wheel.obj"/>
      </geometry>
      <material name="orange"/>
    </visual>
    <collision>
      <origin rpy="1.570796326794895 0 0" xyz="0 0 0"/>
      <geometry>
        <cylinder length="0.01" radius="0.051"/>
      </geometry>
    </collision>
    <inertial>
      <origin rpy="0 0 0" xyz="0 0 0"/>
      <mass value="0.03"/>
      <inertia ixx="1.9000000000000004e-05" ixy="0.0" ixz="0.0" iyy="1.9000000000000004e-05" iyz="0.0" izz="3.7500000000000003e-05"/>
    </inertial>
  </link>
  <joint name="base_to_right_wheel" type="continuous">
    <parent link="chassis_link"/>
    <child link="right_wheel_link"/>
    <origin rpy="0 0 0" xyz="0.051 -0.09 0"/>
    <axis xyz="0 1 0"/>
  </joint>


  <!-- Left wheel -->
  <link name="left_wheel_link">
    <visual>
      <origin rpy="-3.14 0 0" xyz="0 0 0"/>
      <geometry>
        <mesh filename="../meshes/puzzlebot_wheel.obj"/>
      </geometry>
      <material name="orange"/>
    </visual>
    <collision>
      <origin rpy="1.570796326794895 0 0" xyz="0 0 0"/>
      <geometry>
        <cylinder length="0.01" radius="0.051"/>
      </geometry>
    </collision>
    <inertial>
      <origin rpy="0 0 0" xyz="0 0 0"/>
      <mass value="0.03"/>
      <inertia ixx="1.9000000000000004e-05" ixy="0.0" ixz="0.0" iyy="1.9000000000000004e-05" iyz="0.0" izz="3.7500000000000003e-05"/>
    </inertial>
  </link>
  <joint name="base_to_left_wheel" type="continuous">
    <parent link="chassis_link"/>
    <child link="left_wheel_link"/>
    <origin rpy="0 0 0" xyz="0.051 0.09 0"/>
    <axis xyz="0 1 0"/>
  </joint>


  <!-- camera -->
  <link name="camera_link">
    <collision>
      <origin rpy="0 0 0" xyz="0.0 0 0.0"/>
      <geometry>
        <box size="0.05 0.01 0.06"/>
      </geometry>
    </collision>
    <inertial>
      <origin rpy="0 0 0" xyz="0 0 0"/>
      <mass value="0.007"/>
      <inertia ixx="2.1583333333333336e-06" ixy="0.0" ixz="0.0" iyy="3.5583333333333337e-06" iyz="0.0" izz="1.516666666666667e-06"/>
    </inertial>
  </link>
  <joint name="chassis_to_camera" type="fixed">
    <parent link="chassis_link"/>
    <child link="camera_link"/>
    <origin rpy="0 0 0" xyz="0.1 0 0.07"/>
  </joint>s
  
  
  
  <!-- camera opticual frame -->
  <link name="camera_color_optical_frame">
    <collision>
      <origin rpy="0 0 0" xyz="0 0 0"/>
      <geometry>
        <box size="0.05 0.01 0.06"/>
      </geometry>
    </collision>
    <inertial>
      <origin rpy="0 0 0" xyz="0 0 0"/>
      <mass value="0.007"/>
      <inertia ixx="2.1583333333333336e-06" ixy="0.0" ixz="0.0" iyy="3.5583333333333337e-06" iyz="0.0" izz="1.516666666666667e-06"/>
    </inertial>
  </link>
  <joint name="optical_frame" type="fixed">
    <parent link="camera_link"/>
    <child link="camera_color_optical_frame"/>
    <origin rpy="-1.570796326794895 0 -1.570796326794895" xyz="0.02 0 0"/>
  </joint>


  <!-- lidar -->
  <link name="lidar_link">
    <collision>
      <origin rpy="0 0 0" xyz="0 0 0"/>
      <geometry>
        <cylinder length="0.04" radius="0.05"/>
      </geometry>
    </collision>
    <inertial>
      <origin rpy="0 0 0" xyz="0 0 0"/>
      <mass value="0.1"/>
      <inertia ixx="7.583333333333335e-05" ixy="0.0" ixz="0.0" iyy="7.583333333333335e-05" iyz="0.0" izz="0.00012500000000000003"/>
    </inertial>
  </link>
  <joint name="chassis_to_lidar" type="fixed">
    <parent link="chassis_link"/>
    <child link="lidar_link"/>
    <origin rpy="0 0 3.14159265358979" xyz="0.05 0.0 0.115"/>
  </joint>
</robot>
